<?xml version="1.0" encoding="UTF-8"?>
<!-- Generated by org.testng.reporters.JUnitXMLReporter -->
<testsuite hostname="VAIO" ignored="0" name="SeleniumTest1" tests="1" failures="1" timestamp="2020-08-14T14:47:41 IST" time="44.341" errors="0">
  <testcase name="@AfterClass writeExtentReport" time="0.015" classname="com.qa.auto.modules.TestRunner1">
    <failure type="java.lang.NullPointerException">
      <![CDATA[java.lang.NullPointerException
at com.qa.auto.modules.TestRunner1.writeExtentReport(TestRunner1.java:28)
at sun.reflect.NativeMethodAccessorImpl.invoke0(Native Method)
at sun.reflect.NativeMethodAccessorImpl.invoke(Unknown Source)
at sun.reflect.DelegatingMethodAccessorImpl.invoke(Unknown Source)
at java.lang.reflect.Method.invoke(Unknown Source)
at org.testng.internal.MethodInvocationHelper.invokeMethod(MethodInvocationHelper.java:133)
at org.testng.internal.MethodInvocationHelper.invokeMethodConsideringTimeout(MethodInvocationHelper.java:62)
at org.testng.internal.ConfigInvoker.invokeConfigurationMethod(ConfigInvoker.java:340)
at org.testng.internal.ConfigInvoker.invokeConfigurations(ConfigInvoker.java:294)
at org.testng.internal.TestMethodWorker.invokeAfterClassMethods(TestMethodWorker.java:217)
at org.testng.internal.TestMethodWorker.run(TestMethodWorker.java:130)
at java.util.ArrayList.forEach(Unknown Source)
at org.testng.TestRunner.privateRun(TestRunner.java:770)
at org.testng.TestRunner.run(TestRunner.java:591)
at org.testng.SuiteRunner.runTest(SuiteRunner.java:402)
at org.testng.SuiteRunner.access$000(SuiteRunner.java:41)
at org.testng.SuiteRunner$SuiteWorker.run(SuiteRunner.java:443)
at org.testng.internal.thread.ThreadUtil.lambda$execute$0(ThreadUtil.java:67)
at java.util.concurrent.FutureTask.run(Unknown Source)
at java.util.concurrent.ThreadPoolExecutor.runWorker(Unknown Source)
at java.util.concurrent.ThreadPoolExecutor$Worker.run(Unknown Source)
at java.lang.Thread.run(Unknown Source)
]]>
    </failure>
  </testcase> <!-- @AfterClass writeExtentReport -->
  <testcase name="feature" time="43.56" classname="cucumber.api.testng.AbstractTestNGCucumberTests">
    <failure type="cucumber.runtime.CucumberException" message="java.lang.AssertionError: expected [Invalid datee] but found [Invalid date]">
      <![CDATA[cucumber.runtime.CucumberException: java.lang.AssertionError: expected [Invalid datee] but found [Invalid date]
at cucumber.api.testng.TestNGCucumberRunner.runCucumber(TestNGCucumberRunner.java:69)
at cucumber.api.testng.AbstractTestNGCucumberTests.feature(AbstractTestNGCucumberTests.java:21)
at sun.reflect.NativeMethodAccessorImpl.invoke0(Native Method)
at sun.reflect.NativeMethodAccessorImpl.invoke(Unknown Source)
at sun.reflect.DelegatingMethodAccessorImpl.invoke(Unknown Source)
at java.lang.reflect.Method.invoke(Unknown Source)
at org.testng.internal.MethodInvocationHelper.invokeMethod(MethodInvocationHelper.java:133)
at org.testng.internal.TestInvoker.invokeMethod(TestInvoker.java:584)
at org.testng.internal.TestInvoker.invokeTestMethod(TestInvoker.java:172)
at org.testng.internal.MethodRunner.runInSequence(MethodRunner.java:46)
at org.testng.internal.TestInvoker$MethodInvocationAgent.invoke(TestInvoker.java:804)
at org.testng.internal.TestInvoker.invokeTestMethods(TestInvoker.java:145)
at org.testng.internal.TestMethodWorker.invokeTestMethods(TestMethodWorker.java:146)
at org.testng.internal.TestMethodWorker.run(TestMethodWorker.java:128)
at java.util.ArrayList.forEach(Unknown Source)
at org.testng.TestRunner.privateRun(TestRunner.java:770)
at org.testng.TestRunner.run(TestRunner.java:591)
at org.testng.SuiteRunner.runTest(SuiteRunner.java:402)
at org.testng.SuiteRunner.access$000(SuiteRunner.java:41)
at org.testng.SuiteRunner$SuiteWorker.run(SuiteRunner.java:443)
at org.testng.internal.thread.ThreadUtil.lambda$execute$0(ThreadUtil.java:67)
at java.util.concurrent.FutureTask.run(Unknown Source)
at java.util.concurrent.ThreadPoolExecutor.runWorker(Unknown Source)
at java.util.concurrent.ThreadPoolExecutor$Worker.run(Unknown Source)
at java.lang.Thread.run(Unknown Source)
Caused by: java.lang.AssertionError: expected [Invalid datee] but found [Invalid date]
at org.testng.Assert.fail(Assert.java:97)
at org.testng.Assert.assertEqualsImpl(Assert.java:136)
at org.testng.Assert.assertEquals(Assert.java:118)
at org.testng.Assert.assertEquals(Assert.java:575)
at org.testng.Assert.assertEquals(Assert.java:585)
at com.qa.auto.stepdefination.HomePage.check_the_output_Invalid_Date_field(HomePage.java:31)
at âœ½.Then Check the output 'Invalid datee' field(HomePage1.feature:8)
]]>
    </failure>
  </testcase> <!-- feature -->
</testsuite> <!-- SeleniumTest1 -->
